# 柯特林多抓块

> 原文：<https://www.javatpoint.com/kotlin-multiple-catch-block>

我们可以在代码中使用多个 catch 块。当我们在 try 块中使用不同类型的操作时，使用了 Kotlin 多个 catch 块，这可能会导致 try 块中出现不同的异常。

### Kotlin 多重捕捉块示例 1

让我们看一个多重捕捉块的例子。在这个例子中，我们将执行不同类型的操作。这些不同类型的操作可能会产生不同类型的异常。

```

 fun main(args: Array<String>){
    try {
        val a = IntArray(5)
        a[5] = 10 / 0
    } catch (e: ArithmeticException) {
        println("arithmetic exception catch")
    } catch (e: ArrayIndexOutOfBoundsException) {
        println("array index outofbounds exception")
    } catch (e: Exception) {
        println("parent exception class")
    }
    println("code after try catch...")
}

```

**输出:**

```
arithmetic exception catch
code after try catch...

```

#### 注意:一次只出现一个异常，一次只执行一个 catch 块。

**规则:**所有捕获块必须从最具体到一般放置，即算术异常的捕获必须在异常的捕获之前。

### 当我们从一般异常捕捉到特定异常时会发生什么？

它会产生警告。例如:

让我们修改上面的代码，将 catch 块从一般异常放到特定异常。

```

fun main(args: Array<String>){
    try {
        val a = IntArray(5)
        a[5] = 10 / 0
    }
    catch (e: Exception) {
        println("parent exception catch")
    }
    catch (e: ArithmeticException) {
        println("arithmetic exception catch")
    } catch (e: ArrayIndexOutOfBoundsException) {
        println("array index outofbounds exception")
    }

    println("code after try catch...")
}

```

**编译时输出**

```
warning : division by zero
a[5] = 10/0

```

**运行时输出**

```
parent exception catch
code after try catch...

```