# 省道例外

> 原文:[https://www.javatpoint.com/dart-exceptions](https://www.javatpoint.com/dart-exceptions)

Dart 异常是运行时错误。它在程序执行时引发。当程序在内部运行时，如果 Dart 编译器发现一些不合适的地方，程序不会在编译时报告错误。然后，它报告运行时错误，程序执行异常终止。这种类型的错误称为异常。例如-给定的数字除以零，或者我们尝试从空列表中访问元素。

Dart 支持以下类型的内置异常。

| Sr | 例外 | 描述 |
| **1。** | DefferedLoadException | 当延迟库未能加载时，将引发该事件。 |
| **2。** | 格式异常 | 引发的是异常 |
| **3。** | integerdivisionionbyzeroexception | 当数被零除时抛出。 |
| **4。** | 异常 | 它是输入输出相关异常的基类。 |
| **5。** | IsolateSpawnException | 当无法创建隔离的时抛出。 |
| **6。** | 超时 | 当等待异步结果时发生计划超时时，将引发该事件。 |

异常的主要目的是处理运行时错误，防止程序突然终止。Dart 中的每个异常都是预定义类**异常**的子类型。Dart 提供了以下技术来处理异常。

### 试/上/抓积木

try 块用于保存可能引发异常的代码块。on 块用于当我们需要指定异常时。catch 块用于确定处理程序何时需要异常对象。

如果 try 块发现了错误，它会抛出 catch 块，catch 块有处理错误的代码。 **try** 区块后面必须紧跟一个区块，要么是 on/ catch，要么是 finally 区块。

异常处理的语法如下。

### 语法:

```
try {
// code that might throw an exception
}
on Exception1 {
// Specify the exception
}
Catch Exception2 {
// code for handling exception
}

```

人们应该记住以下几点。

*   我们可以使用多个 catch 块来处理多个异常。

*   on 块和 catch 块是相互包含的，这意味着我们可以将 on 块和 catch 块与 try 块关联起来。

在下面的例子中，变量 x 分别除以 y 变量。当代码试图除以零时，将引发。on 块由处理异常的代码组成。让我们理解下面的代码。

### 示例-使用 on 块

```

void main() { 
   int x = 12; 
   int y = 0; 
   int res;  

   try {
      res = x ~/ y; 
   } 
   on IntegerDivisionByZeroException { 
      print('Cannot divide by zero'); 
   } 
}

```

**输出**

```
Cannot divide by zero

```

**说明:**

在上面的代码中，我们在 **main ()** 函数中声明了三个变量 **x，y** 和 **res** 。我们在 try 块中编写了可疑代码，用 x 除以可能引发异常的 0。try 块发现了控制转移到具有处理错误代码的 on 块的错误。通过使用这个，程序并没有停止它的执行。

让我们使用 catch 块来理解下面的示例。

### 示例-使用捕捉块

```

void main() { 
   int x = 12; 
   int y = 0; 
   int res;  

   try {  
      res = x ~/ y; 
   }  
// It returns the built-in exception related to the occurring exception
   catch(E) { 
      print(E); 
   } 
}

```

**输出**

```
IntegerDivisionByZeroException

```

现在看看 on…一起抓块的例子

### 示例 3:在…捕捉块上

```

void main() { 
   int x = 12; 
   int y = 0; 
   int res;  

   try { 
      res = x ~/ y; 
   }  
   on IntegerDivisionByZeroException catch(E) { 
      print(E); 
   } 
}

```

**输出**

```
IntegerDivisionByZeroException

```

## 最后一块

不管是否出现异常，finally 块总是执行。它在 try/on/catch 之后无条件执行。

finally 块的语法如下所示。

### 语法-

```

try { 
   // code that may be throw an exception 
}  
on Exception1 { 
   // exception handling code or specifying the exception
}  
catch Exception2 { 
   //  code for exception handling 
}  
finally { 
   // code that should always execute; whether exception or not.
}

```

让我们理解下面的 finally block 示例。

### 示例-

```

   finally { void main() { 
   int x = 12; 
   int y = 0; 
   int res;  

   try { 
      res = x ~/ y; 
   } 
   on IntegerDivisionByZeroException { 
      print('Cannot divide by zero'); 
   } 

      print('Finally block always executed'); 
   } 
}

```

**输出**

```
Cannot divide by zero 
Finally block executed

```

## 引发异常

我们可以显式或强制地引发异常。应该处理显式引发的异常，以避免程序急剧存在。语法如下。

### 语法:

```

throw new Exception_name()

```

让我们理解下面的例子。

### 示例-

```

main() { 
   try { 
      check_marks(-10); 
   } 
   catch(e) { 
      print('The marks cannot be negative'); 
   } 
}  
void check_marks(int marks) { 
   if(marks<0) { 
      throw new FormatException();  // Raising explanation externally
   } 
}

```

**输出**

```
The marks cannot be negative

```

### 自定义例外

如上所述，dart 中的每个异常都是内置类**异常**的子类型。Dart 通过扩展现有的异常类，提供了创建自定义异常的灵活性。语法如下。

### 语法:定义异常

```

class Custom_exception_Name implements Exception { 
   // can contain constructors, variables and methods 
} 

```

让我们理解下面的代码。

### 示例-

```

class AmtException implements Exception { 
   String expMsg() => 'Entered Amount should be greater than zero'; 
}  
void main() { 
   try { 
      withdraw_amt(-1); 
   } 
   catch(E) { 
      print(E.expMsg()); 
   }  
   finally { 
      print('Ending requested operation.....'); 
   } 
}  
void withdraw_amt(int amt) { 
   if (amt <= 0) { 
      throw new AmtException(); 
   } 
}  

```

**输出**

```
Entered Amount should be greater than zero
Ending requested operation.....

```

### 解释:

在上面的例子中，我们创建了一个自定义异常，**amtexexception**。如果输入的数量不在异常范围内，代码将引发异常，我们将函数调用包含在 try…catch 块中。

* * *